<?xml version="1.0"?>
<robot name="simple_bot" xmlns:xacro="http://ros.org/wiki/xacro">

  <!-- Materials -->
  <material name="red">
    <color rgba="0.6 0.0 0.0 1"/>
  </material>
  <material name="black">
    <color rgba="0.1 0.1 0.1 1"/>
  </material>
  <material name="grey">
    <color rgba="0.5 0.5 0.5 1"/>
  </material>

  <!-- Links -->
  <link name="aruco_base_descr"/>
  <link name="aruco_base_link">
  <visual>
    <geometry>
      <box size="0.6 0.4 0.2"/>
    </geometry>

    <origin xyz="0.0 0.0 0.0" rpy="0.0 0.0 0.0"/>
  </visual>

  <collision>
    <geometry>
      <box size="0.6 0.4 0.2"/>
    </geometry>
    <origin xyz="0.0 0.0 0.0" rpy="0.0 0.0 0"/>
  </collision>

  <inertial>
    <mass value="5.0"/>
    <origin xyz="0 0 0" rpy="0 0 0"/>
    <inertia 
      ixx="0.1" ixy="0.0" ixz="0.0"
      iyy="0.1" iyz="0.0"
      izz="0.1"/>
  </inertial>
</link>

<link name="aruco_marker_panel">
  <visual>
    <geometry>
      <box size="0.01 1 1"/> <!-- a thin square -->
    </geometry>
    <origin xyz="0.3 0.0 0.1" rpy="0 1.57 0"/> <!-- adjust side & rotation -->
  </visual>
</link>

<gazebo reference="aruco_marker_panel">
  <material>
    <script>
      <uri>file:///home/pranabpandey31/rostasks/task3_part1/install/task3_part1_bot/share/task3_part1_bot/world/</uri>
      <name>aruco_marker_0</name>
    </script>
  </material>
</gazebo>

<joint name="aruco_marker_joint" type="fixed">
  <parent link="aruco_base_link"/>
  <child link="aruco_marker_panel"/>
  <origin xyz="0.2 0.0 0.1" rpy="0 0 0"/>
</joint>

  <link name="aruco_left_wheel">
    <visual>
      <geometry>
        <cylinder length="0.05" radius="0.1"/>
      </geometry>
      <origin xyz="0 0 0" rpy="0 0 0"/>
      <material name="black"/>
    </visual>
    <collision>
    <geometry>
      <cylinder radius="0.1" length="0.05"/>
    </geometry>
    <origin xyz="0.0 0.0 0.0" rpy="0.0 0.0 0"/>
  </collision>
  <inertial>
    <mass value="0.5"/>
    <origin xyz="0 0 0" rpy="0 0 0"/>
    <inertia 
      ixx="0.1" ixy="0.0" ixz="0.0"
      iyy="0.1" iyz="0.0"
      izz="0.1"/>
  </inertial>
  </link>

  <link name="aruco_right_wheel">
    <visual>
      <geometry>
        <cylinder length="0.05" radius="0.1"/>
      </geometry>
      <origin xyz="0 0 0" rpy="0.0 0 0"/>
      <material name="black"/>
    </visual>
    <collision>
    <geometry>
      <cylinder radius="0.1" length="0.05"/>
    </geometry>
    <origin xyz="0.0 0.0 0.0" rpy="0.0 0.0 0"/>
  </collision>

  <inertial>
    <mass value="2.0"/>
    <origin xyz="0 0 0" rpy="0 0 0"/>
    <inertia 
      ixx="0.1" ixy="0.0" ixz="0.0"
      iyy="0.1" iyz="0.0"
      izz="0.1"/>
  </inertial>
  </link>
  

  <link name="aruco_caster_wheel">
    <visual>
      <geometry>
        <sphere radius="0.1"/>
      </geometry>
      <material name="grey"/>
    </visual>
    <collision>
    
    <geometry>
      <sphere radius="0.1"/>
    </geometry>
  </collision>

  <inertial>
    <mass value="0.05"/>
    <origin xyz="0 0 0" rpy="0 0 0"/>
    <inertia 
      ixx="0.1" ixy="0.0" ixz="0.0"
      iyy="0.1" iyz="0.0"
      izz="0.1"/>
  </inertial>
  </link>

  <!-- Joints -->
  <joint name="aruco_left_wheel_joint" type="continuous">
    <parent link="aruco_base_link"/>
    <child link="aruco_left_wheel"/>
    <origin xyz="-0.15 0.25 -0.1" rpy="1.57 0 3.141"/>
    <axis xyz="0.0 0.0 1"/>
  </joint>

  <joint name="aruco_right_wheel_joint" type="continuous">
    <parent link="aruco_base_link"/>
    <child link="aruco_right_wheel"/>
    <origin xyz="-0.15 -0.25 -0.1" rpy="1.57 0 3.141"/>
    <axis xyz="0.0 0.0 1"/>
  </joint>

  <joint name="aruco_caster_wheel_joint" type="fixed">
  <parent link="aruco_base_link"/>
  <child link="aruco_caster_wheel"/>
  <origin xyz="0.15 0 -0.1" rpy="0 0 0.0"/>
  </joint>

  <joint name="aruco_base" type="fixed">
    <parent link="aruco_base_descr"/>
    <child link="aruco_base_link"/>
    <origin rpy="0.0 0.0 3.141"/>
  </joint>

  <gazebo reference="aruco_right_wheel">
  <material>Gazebo/Grey</material>
  <pose>0 0 0 0 0 0</pose>
  <mu1>0.5</mu1>
  <mu2>0.5</mu2>
  </gazebo>
  <gazebo reference="aruco_caster_wheel">
  <material>Gazebo/Grey</material>
  <mu1>0</mu1>
  <mu2>0</mu2>
  </gazebo>
  <gazebo reference="aruco_left_wheel">
  <material>Gazebo/Grey</material>
  <pose>0 0 0 0 0 0</pose>
  <mu1>0.5</mu1>
  <mu2>0.5</mu2>
  </gazebo>
  <gazebo reference="aruco_base_link">
  <material>Gazebo/Red</material>
  <pose>0 0 0 0 0 3.1416</pose>
  </gazebo>
  <gazebo>
  <plugin name="diff_drive_controller" filename="libgazebo_ros_diff_drive.so">
    <ros>
      <remapping>cmd_vel:=/cmd_vel</remapping>
    </ros>
    <update_rate>50.0</update_rate>
    <left_joint>aruco_left_wheel_joint</left_joint>
    <right_joint>aruco_right_wheel_joint</right_joint>
    <wheel_separation>0.5</wheel_separation>
    <wheel_diameter>0.3</wheel_diameter>
    <use_sim_time>true</use_sim_time>
    <command_topic>aruco/cmd_vel</command_topic>
    <publish_odom>true</publish_odom>
      <publish_odom_tf>true</publish_odom_tf>
      <publish_wheel_tf>false</publish_wheel_tf>
  <max_wheel_acceleration>20.0</max_wheel_acceleration>
    <odometry_topic>aruco/odom</odometry_topic>
    <odometry_frame>odom</odometry_frame>
    <robot_base_frame>aruco_base_link</robot_base_frame>
    <publish_tf>true</publish_tf>
  </plugin>
</gazebo>

</robot>
