<?xml version="1.0"?>
<robot name="simple_bot" xmlns:xacro="http://ros.org/wiki/xacro">

  <!-- Materials -->
  <material name="red">
    <color rgba="0.6 0.0 0.0 1"/>
  </material>
  <material name="black">
    <color rgba="0.1 0.1 0.1 1"/>
  </material>
  <material name="grey">
    <color rgba="0.5 0.5 0.5 1"/>
  </material>

  <!-- Links -->
  <link name="base_descr"/>
  <link name="base_link">
    <visual>
      <geometry>
        <box size="0.6 0.4 0.2"/>
      </geometry>
      <origin xyz="0.0 0.0 0.0" rpy="0.0 0.0 0.0"/>
      <material name="red"/>
    </visual>

    <collision>
    <geometry>
      <box size="0.6 0.4 0.2"/>
    </geometry>
    <origin xyz="0.0 0.0 0.0" rpy="0.0 0.0 0"/>
    </collision>

    <inertial>
    <mass value="5.0"/>
    <origin xyz="0 0 0" rpy="0 0 0"/>
    <inertia 
      ixx="0.1" ixy="0.0" ixz="0.0"
      iyy="0.1" iyz="0.0"
      izz="0.1"/>
    </inertial>
  </link>
  <link name="camera1">
    <visual>
      <geometry>
        <box size="0.1 0.1 0.05"/>
      </geometry>
      <origin xyz="0.0 0.0 0.0" rpy="0.0 0.0 0.0"/>
      <material name="black"/>
    </visual>

    <collision>
    <geometry>
      <box size="0.1 0.1 0.05"/>
    </geometry>
    <origin xyz="0.0 0.0 0.0" rpy="0.0 0.0 0.0"/>
    </collision>

    <inertial>
    <mass value="0.5"/>
    <origin xyz="0 0 0" rpy="0 0 0"/>
    <inertia 
      ixx="0.1" ixy="0.0" ixz="0.0"
      iyy="0.1" iyz="0.0"
      izz="0.1"/>
    </inertial>
  </link>


  <link name="camera2">
    <visual>
      <geometry>
        <box size="0.1 0.1 0.05"/>
      </geometry>
      <origin xyz="0.0 0.0 0.0" rpy="0.0 0.0 0.0"/>
      <material name="black"/>
    </visual>

    <collision>
    <geometry>
      <box size="0.1 0.1 0.05"/>
    </geometry>
    <origin xyz="0.0 0.0 0.0" rpy="0.0 0.0 0.0"/>
    </collision>

    <inertial>
    <mass value="0.5"/>
    <origin xyz="0 0 0" rpy="0 0 0"/>
    <inertia 
      ixx="0.1" ixy="0.0" ixz="0.0"
      iyy="0.1" iyz="0.0"
      izz="0.1"/>
    </inertial>
  </link>

  <link name="camera3">
    <visual>
      <geometry>
        <box size="0.1 0.1 0.05"/>
      </geometry>
      <origin xyz="0.0 0.0 0.0" rpy="0.0 0.0 0.0"/>
      <material name="black"/>
    </visual>

    <collision>
    <geometry>
      <box size="0.1 0.1 0.05"/>
    </geometry>
    <origin xyz="0.0 0.0 0.0" rpy="0.0 0.0 0.0"/>
    </collision>

    <inertial>
    <mass value="0.5"/>
    <origin xyz="0 0 0" rpy="0 0 0"/>
    <inertia 
      ixx="0.1" ixy="0.0" ixz="0.0"
      iyy="0.1" iyz="0.0"
      izz="0.1"/>
    </inertial>
  </link>

  <link name="left_wheel">
    <visual>
      <geometry>
        <cylinder length="0.05" radius="0.1"/>
      </geometry>
      <origin xyz="0 0 0" rpy="0 0 0"/>
      <material name="black"/>
    </visual>
    <collision>
    <geometry>
      <cylinder radius="0.1" length="0.05"/>
    </geometry>
    <origin xyz="0.0 0.0 0.0" rpy="0.0 0.0 0"/>
  </collision>
  <inertial>
    <mass value="0.5"/>
    <origin xyz="0 0 0" rpy="0 0 0"/>
    <inertia 
      ixx="0.1" ixy="0.0" ixz="0.0"
      iyy="0.1" iyz="0.0"
      izz="0.1"/>
  </inertial>
  </link>

  <link name="right_wheel">
    <visual>
      <geometry>
        <cylinder length="0.05" radius="0.1"/>
      </geometry>
      <origin xyz="0 0 0" rpy="0.0 0 0"/>
      <material name="black"/>
    </visual>
    <collision>
    <geometry>
      <cylinder radius="0.1" length="0.05"/>
    </geometry>
    <origin xyz="0.0 0.0 0.0" rpy="0.0 0.0 0"/>
  </collision>

  <inertial>
    <mass value="2.0"/>
    <origin xyz="0 0 0" rpy="0 0 0"/>
    <inertia 
      ixx="0.1" ixy="0.0" ixz="0.0"
      iyy="0.1" iyz="0.0"
      izz="0.1"/>
  </inertial>
  </link>
  

  <link name="caster_wheel">
    <visual>
      <geometry>
        <sphere radius="0.1"/>
      </geometry>
      <material name="grey"/>
    </visual>
    <collision>
    
    <geometry>
      <sphere radius="0.1"/>
    </geometry>
  </collision>

  <inertial>
    <mass value="0.05"/>
    <origin xyz="0 0 0" rpy="0 0 0"/>
    <inertia 
      ixx="0.1" ixy="0.0" ixz="0.0"
      iyy="0.1" iyz="0.0"
      izz="0.1"/>
  </inertial>
  </link>

  <!-- Joints -->
  <joint name="left_wheel_joint" type="continuous">
    <parent link="base_link"/>
    <child link="left_wheel"/>
    <origin xyz="-0.15 0.25 -0.1" rpy="1.57 0 3.141"/>
    <axis xyz="0.0 0.0 1"/>
  </joint>
  <joint name="camera1_base_joint" type="fixed">
    <parent link="base_link"/>
    <child link="camera1"/>
    <origin xyz="0.2 0 0.15" rpy="0 0 0"/>
  </joint>

  <joint name="camera2_base_joint" type="fixed">
    <parent link="base_link"/>
    <child link="camera2"/>
    <origin xyz="0.0 0.15 0.15" rpy="0 0 1.57"/>
  </joint>

  <joint name="camera3_base_joint" type="fixed">
    <parent link="base_link"/>
    <child link="camera3"/>
    <origin xyz="0.0 -0.15 0.15" rpy="0 0 -1.57"/>
  </joint>

  <joint name="right_wheel_joint" type="continuous">
    <parent link="base_link"/>
    <child link="right_wheel"/>
    <origin xyz="-0.15 -0.25 -0.1" rpy="1.57 0 3.141"/>
    <axis xyz="0.0 0.0 1"/>
  </joint>

  <joint name="caster_wheel_joint" type="fixed">
  <parent link="base_link"/>
  <child link="caster_wheel"/>
  <origin xyz="0.15 0 -0.1" rpy="0 0 0.0"/>
  </joint>

  <joint name="base" type="fixed">
    <parent link="base_descr"/>
    <child link="base_link"/>
    <origin rpy="0.0 0.0 3.141"/>
  </joint>

  <gazebo reference="right_wheel">
  <material>Gazebo/Grey</material>
  <pose>0 0 0 0 0 0</pose>
  <mu1>0.5</mu1>
  <mu2>0.5</mu2>
  </gazebo>
  <gazebo reference="caster_wheel">
  <material>Gazebo/Grey</material>
  <mu1>0</mu1>
  <mu2>0</mu2>
  </gazebo>
  <gazebo reference="left_wheel">
  <material>Gazebo/Grey</material>
  <pose>0 0 0 0 0 0</pose>
  <mu1>0.5</mu1>
  <mu2>0.5</mu2>
  </gazebo>
  <gazebo reference="base_link">
  <material>Gazebo/Red</material>
  <pose>0 0 0 0 0 3.1416</pose>
  </gazebo>
  <!-- Add Camera Plugin Here -->
  <gazebo reference="camera1">
  <material>Gazebo/Black</material>
    <sensor type="camera" name="camera_sensor">
      <camera>
        <horizontal_fov>1.396</horizontal_fov>
        <image>
          <width>640</width>
          <height>480</height>
          <format>R8G8B8</format>
        </image>
        <clip>
          <near>0.1</near>
          <far>100</far>
        </clip>
      </camera>
      <plugin name="camera_controller1" filename="libgazebo_ros_camera.so">
        <camera_name>camera1</camera_name>
        <image_topic_name>image_raw</image_topic_name>
        <camera_info_topic_name>camera_info</camera_info_topic_name>
        <frame_name>camera1</frame_name>
      </plugin>
    </sensor>
  </gazebo>


  <gazebo reference="camera2">
  <material>Gazebo/Black</material>
    <sensor type="camera" name="camera_sensor">
      <camera>
        <horizontal_fov>1.396</horizontal_fov>
        <image>
          <width>640</width>
          <height>480</height>
          <format>R8G8B8</format>
        </image>
        <clip>
          <near>0.1</near>
          <far>100</far>
        </clip>
      </camera>
      <plugin name="camera_controller2" filename="libgazebo_ros_camera.so">
        <camera_name>camera2</camera_name>
        <image_topic_name>image_raw</image_topic_name>
        <camera_info_topic_name>camera_info</camera_info_topic_name>
        <frame_name>camera2</frame_name>
      </plugin>
    </sensor>
  </gazebo>

  <gazebo reference="camera3">
  <material>Gazebo/Black</material>
    <sensor type="camera" name="camera_sensor">
      <camera>
        <horizontal_fov>1.396</horizontal_fov>
        <image>
          <width>640</width>
          <height>480</height>
          <format>R8G8B8</format>
        </image>
        <clip>
          <near>0.1</near>
          <far>100</far>
        </clip>
      </camera>
      <plugin name="camera_controller3" filename="libgazebo_ros_camera.so">
        <camera_name>camera3</camera_name>
        <image_topic_name>image_raw</image_topic_name>
        <camera_info_topic_name>camera_info</camera_info_topic_name>
        <frame_name>camera3</frame_name>
      </plugin>
    </sensor>
  </gazebo>

  <gazebo>
  <plugin name="follower_diff_drive_controller" filename="libgazebo_ros_diff_drive.so">
      <ros>
        <remapping>cmd_vel:=/cmd_vel</remapping>
      </ros>
      <update_rate>50</update_rate>
      <left_joint>left_wheel_joint</left_joint>
      <right_joint>right_wheel_joint</right_joint>
      <wheel_separation>0.5</wheel_separation>
      <wheel_diameter>0.3</wheel_diameter>
      <use_sim_time>true</use_sim_time>
      <publish_odom>true</publish_odom>
      <publish_odom_tf>true</publish_odom_tf>
      <publish_wheel_tf>false</publish_wheel_tf>
      <max_wheel_acceleration>20</max_wheel_acceleration>
      <odometry_topic>/odom</odometry_topic>
      <odometry_frame>odom</odometry_frame>
      <robot_base_frame>base_link</robot_base_frame>
    </plugin>
  </gazebo>

</robot>
